<?xml version="1.0"?>

<robot xmlns:sensor="http://playerstage.sourceforge.net/gazebo/xmlschema/#sensor"
       xmlns:controller="http://playerstage.sourceforge.net/gazebo/xmlschema/#controller"
       xmlns:interface="http://playerstage.sourceforge.net/gazebo/xmlschema/#interface"
       xmlns:xacro="http://ros.org/wiki/xacro"
>

<!-- Chassis -->
	<link name="mobile_link">
		
		<!--  For pointers on inertial and gazebo-related parameters see
		       * http://wiki.ros.org/urdf/Tutorials/Adding%20Physical%20and%20Collision%20Properties%20to%20a%20URDF%20Model
                       * http://answers.gazebosim.org/question/4372/the-inertia-matrix-explained/
		       * http://gazebosim.org/tutorials?tut=inertia&cat=build_robot, and 
                       * http://gazebosim.org/tutorials/?tut=ros_urdf
                       * http://en.wikipedia.org/wiki/List_of_moment_of_inertia_tensors  
                -->
		<inertial>
			<mass value="23.088"/> <!-- P3AT 12.0kg plus seven batteries @ 2.384kg each  minus four wheels @ 1.4 kg each and top plate @ 0.1 kg-->
			<origin xyz="-0.1351 0 0.085"/>
			<!-- <inertia ixx="0.3338" ixy="0.0"    ixz="0.0"
				                   iyy="0.4783" iyz="0.0"
				                                izz="0.3338"/> -->
			<inertia ixx="1.382541E-01" ixy="3.279839E-04" ixz="6.369386E-04"
				                    iyy="8.152719E-01" iyz="2.900847E-04"
				                                       izz="8.593085E-01"/>
		</inertial>
		<visual>
			<origin xyz="0 0 0.177" rpy="0 0 0"/>
			<geometry name="pioneer_geom">
				<mesh filename="package://p2os_urdf/meshes/p3at_meshes/chassis.stl"/>
			</geometry>
			<material name="ChassisRed">
				<color rgba="0.851 0.0 0.0 1.0"/>
			</material>
		</visual>
		<collision>
			<origin xyz="0 0 0.177" rpy="0 0 0"/>
				<geometry>
					<mesh filename="package://p2os_urdf/meshes/p3at_meshes/chassis.stl"/>
				</geometry>
		</collision>
	</link>
	<gazebo reference="mobile_link">
		<material value="Gazebo/Red"/>
	</gazebo>

<!-- Top -->
	<link name="top_plate">
		<inertial>
			<mass value="0.1"/>	
			<origin xyz="0 0 0"/>
			<inertia ixx="9.610083E-04" ixy="8.000000E-11" ixz="-4.278400E-07"
				                    iyy="1.758599E-03" iyz="0.0"
 				                                       izz="2.719339E-03"/>
		</inertial>
		<visual>
			<origin xyz="0 0 0" rpy="0 0 0"/>
			<geometry name="pioneer_geom">
				<mesh filename="package://p2os_urdf/meshes/p3at_meshes/top.stl"/>
			</geometry>
			<material name="TopBlack">
					<color rgba="0.038 0.038 0.038 1.0"/>
			</material>
		</visual>
		<collision>
			<origin xyz="0 0 0" rpy="0 0 0"/>
			<geometry>
				<box size="0 0 0"/>
			</geometry>
		</collision>
	</link>
	<gazebo reference="top_plate">
		<material value="Gazebo/Black"/>
	</gazebo>

	<joint name="base_top_joint" type="fixed">
		<origin xyz="0.003 0 0.274" rpy="0 0 0"/>
		<parent link="mobile_link"/>
		<child link="top_plate"/>
	</joint>
<!-- Front + Back Sonar -->
	<link name="front_sonar">
		<inertial>
			<mass value="0.1"/>	
			<origin xyz="0 0 0"/>
			<inertia ixx="1.026329E-03" ixy="-1.100000E-10" ixz="3.000000E-11"
				                    iyy="1.581246E-04"  iyz="1.500000E-10" 
                                                                        izz="1.165954E-03"/>
		</inertial>
		<visual>
			<origin xyz="0 0 0" rpy="0 0 0"/>
			<geometry name="pioneer_geom">
				<mesh filename="package://p2os_urdf/meshes/p3at_meshes/front_sonar.stl"/>
			</geometry>
			<material name="SonarYellow">
				<color rgba="0.715 0.583 0.210 1.0"/>
			</material>
		</visual>
		<collision>
			<origin xyz="0 0 0" rpy="0 0 0"/>
			<geometry>
				<box size="0 0 0"/>
			</geometry>
		</collision>
	</link>
	<gazebo reference="front_sonar">
		<material value="Gazebo/Yellow"/>
	</gazebo>

	<joint name="base_front_joint" type="fixed">
		<origin xyz="0.193 0 0.25" rpy="0 0 0"/>
		<parent link="mobile_link"/>
		<child link="front_sonar"/>
	</joint>

	<link name="back_sonar">
		<inertial>
			<mass value="0.1"/>	
			<origin xyz="0 0 0"/>
			<inertia ixx="4.031719E-04" ixy="3.000000E-11" ixz="0.0"
				                    iyy="6.211593E-05" iyz="-9.000000E-11"
                                                                       izz="4.580205E-04"/>
		</inertial>
		<visual>
			<origin xyz="0 0 0" rpy="0 0 0"/>
			<geometry name="pioneer_geom">
				<mesh filename="package://p2os_urdf/meshes/p3at_meshes/back_sonar.stl"/>
			</geometry>
			<material name="SonarYellow">
				<color rgba="0.715 0.583 0.210 1.0"/>
			</material>
		</visual>
		<collision>
			<origin xyz="0 0 0" rpy="0 0 0"/>
			<geometry>
				<box size="0 0 0"/>
			</geometry>
		</collision>
	</link>
	<gazebo reference="back_sonar">
		<material value="Gazebo/Yellow"/>
	</gazebo>

	<joint name="base_back_joint" type="fixed">
		<origin xyz="-0.187 0 0.247" rpy="0 0 0"/>
		<parent link="mobile_link"/>
		<child link="back_sonar"/>
	</joint>

<!-- Front Axles + Wheels + Hubcaps -->
<xacro:macro name="p3at_front" params="suffix reflect">
	<link name="p3at_front_${suffix}_axle">
		<inertial>
			<mass value="0.1"/>	
			<origin xyz="0 0 0"/>
			<inertia ixx="2.303348E-05" ixy="0.0"          ixz="0.0"
				                    iyy="2.659307E-05" iyz="0.0" 
                                                                       izz="2.303349E-05"/>
  	 	</inertial>
	<visual>
		<origin xyz="0 0 0" rpy="0 0 0"/>
		<geometry name="pioneer_geom">
			<mesh filename="package://p2os_urdf/meshes/p3at_meshes/axle.stl"/>
		</geometry>
		<material name="AxleGrey">
			<color rgba="0.5 0.5 0.5 1"/>
		</material>
	</visual>
	<collision>
		<origin xyz="0 0 0" rpy="0 0 0"/>
		<geometry>
			<box size="0 0 0"/>
		</geometry>
	</collision>
	</link>
	<gazebo reference="p3at_front_${suffix}_axle">
		<material value="Gazebo/Grey"/>
	</gazebo>

	<joint name="base_front_${suffix}_axle_joint" type="fixed">
		<origin xyz="0.135 ${reflect*0.156} 0.111" rpy="0 0 0"/>
		<parent link="mobile_link"/>
		<child link="p3at_front_${suffix}_axle"/>
	</joint>

	<link name="p3at_front_${suffix}_hub">
		<inertial>
			<mass value="0.1"/>	
			<origin xyz="0 0 0"/>
			<inertia ixx="1.520200E-04" ixy="0.0"          ixz="5.100000E-10"
				                    iyy="9.331000E-05" iyz="-1.200000E-10"
                                                                       izz="4.686729E-03"/>
  	 	</inertial>
	<visual>
		<origin xyz="0 0 0" rpy="0 0 0"/>
		<geometry name="pioneer_geom">
			<mesh filename="package://p2os_urdf/meshes/p3at_meshes/${suffix}_hubcap.stl"/>
		</geometry>
		<material name="HubcapYellow">
			<color rgba="1.0 0.811 0.151 1.0"/>
		</material>
	</visual>
	<collision>
		<origin xyz="0 0 0" rpy="0 0 0"/>
		<geometry>
			<box size="0 0 0"/>
		</geometry>
	</collision>
	</link>
	<gazebo reference="p3at_front_${suffix}_hub">
		<material value="Gazebo/Yellow"/>
	</gazebo>

	<joint name="base_front_${suffix}_hub_joint" type="fixed">
		<origin xyz="0 ${reflect*0.041} 0" rpy="0 0 0"/>
		<parent link="p3at_front_${suffix}_axle"/>
		<child link="p3at_front_${suffix}_hub"/>
	</joint>

	<link name="p3at_front_${suffix}_wheel">
		<inertial>
			<mass value="1.2"/>	
			<origin xyz="0 0 0"/>
			<inertia ixx="4.686728E-03" ixy="0.0"          ixz="5.100000E-10"
                                                    iyy="7.787159E-03" iyz="-1.200000E-10"
                                                                       izz="4.686729E-03"/>
                </inertial>
	<visual>
		<origin xyz="0 0 0" rpy="0 0 0"/>
		<geometry name="pioneer_geom">
			<mesh filename="package://p2os_urdf/meshes/p3at_meshes/wheel.stl"/>
		</geometry>
		<material name="WheelBlack">
			<color rgba="0.117 0.117 0.117 1"/>
		</material>
	</visual>
	<collision>
		<origin xyz="0 0 0" rpy="${-3.1415927/2} 0 0"/>
		<geometry>
	    <!--mesh filename="package://p2os_urdf/meshes/p3at_meshes/wheel.stl"/-->
	    <cylinder radius="0.111" length="0.075"/>
		</geometry>
	</collision>
	</link>
	<gazebo reference="p3at_front_${suffix}_wheel">
		<material value="Gazebo/Black"/>
	</gazebo>

	<joint name="p3at_front_${suffix}_wheel_joint" type="continuous">
  	<axis xyz="0 1 0"/>
    <anchor xyz="0 0 0"/>
    <limit effort="100" velocity="100"/>
    <joint_properties damping="0.7"/>
		<origin xyz="0 0 0" rpy="0 0 0"/>
		<parent link="p3at_front_${suffix}_hub"/>
		<child link="p3at_front_${suffix}_wheel"/>
	</joint>
</xacro:macro>
<!-- Back Axles + Wheels + Hubcaps -->
<xacro:macro name="p3at_back" params="suffix reflect">
	<link name="p3at_back_${suffix}_axle">
		<inertial>
			<mass value="0.1"/>	
			<origin xyz="0 0 0"/>
			<inertia ixx="2.303348E-05" ixy="0.0"          ixz="0.0"
				                    iyy="2.659307E-05" iyz="0.0" 
                                                                       izz="2.303349E-05"/>
        	</inertial>
	<visual>
		<origin xyz="0 0 0" rpy="0 0 0"/>
		<geometry name="pioneer_geom">
			<mesh filename="package://p2os_urdf/meshes/p3at_meshes/axle.stl"/>
		</geometry>
		<material name="AxleGrey">
			<color rgba="0.5 0.5 0.5 1"/>
		</material>
	</visual>
	<collision>
		<origin xyz="0 0 0" rpy="0 0 0"/>
		<geometry>
			<mesh filename="package://p2os_urdf/meshes/p3at_meshes/axle.stl"/>
		</geometry>
	</collision>
	</link>
	<gazebo reference="p3at_back_${suffix}_axle">
		<material value="Gazebo/Grey"/>
	</gazebo>

	<joint name="bp3at_back_${suffix}_axle_joint" type="fixed">
		<origin xyz="-0.134 ${reflect*0.156} 0.111" rpy="0 0 0"/>
		<parent link="mobile_link"/>
		<child link="p3at_back_${suffix}_axle"/>
	</joint>


	<link name="p3at_back_${suffix}_hub">
		<inertial>
			<mass value="0.1"/>	
			<origin xyz="0 0 0"/>
			<inertia ixx="1.520200E-04" ixy="0.0"          ixz="5.100000E-10"
				                    iyy="9.331000E-05" iyz="-1.200000E-10"
                                                                       izz="4.686729E-03"/>
  	 	</inertial>
	<visual>
		<origin xyz="0 0 0" rpy="0 0 0"/>
		<geometry name="pioneer_geom">
			<mesh filename="package://p2os_urdf/meshes/p3at_meshes/${suffix}_hubcap.stl"/>
		</geometry>
		<material name="HubcapYellow"/>
	</visual>
	<collision>
		<origin xyz="0 0 0" rpy="0 0 0"/>
		<geometry>
			<mesh filename="package://p2os_urdf/meshes/p3at_meshes/${suffix}_hubcap.stl"/>
		</geometry>
	</collision>
	</link>
	<gazebo reference="p3at_back_${suffix}_hub">
		<material value="Gazebo/Yellow"/>
	</gazebo>

	<joint name="p3at_back_${suffix}_hub_joint" type="fixed">
		<origin xyz="-0 ${reflect*0.041} 0" rpy="0 0 0"/>
		<parent link="p3at_back_${suffix}_axle"/>
		<child link="p3at_back_${suffix}_hub"/>
	</joint>

	<link name="p3at_back_${suffix}_wheel">
		<inertial>
			<mass value="1.2"/>	
			<origin xyz="0 0 0"/>
			<inertia ixx="4.686728E-03" ixy="0.0"          ixz="5.100000E-10"
                                                    iyy="7.787159E-03" iyz="-1.200000E-10"
                                                                       izz="4.686729E-03"/>
                </inertial>
	<visual>
		<origin xyz="0 0 0" rpy="0 0 0"/>
		<geometry name="pioneer_geom">
			<mesh filename="package://p2os_urdf/meshes/p3at_meshes/wheel.stl"/>
		</geometry>
		<material name="WheelBlack"/>
	</visual>
	<collision>
		<origin xyz="0 0 0" rpy="${-3.1415927/2} 0 0"/>
		<geometry>
	    <!--mesh filename="package://p2os_urdf/meshes/p3at_meshes/wheel.stl"/-->
	    <cylinder radius="0.111" length="0.075"/>
		</geometry>
	</collision>
	</link>
	<gazebo reference="p3at_back_${suffix}_wheel">
		<material value="Gazebo/Black"/>
	</gazebo>

	<joint name="p3at_back_${suffix}_wheel_joint" type="continuous">
	  <axis xyz="0 1 0"/>
    <anchor xyz="0 0 0"/>
    <limit effort="100" velocity="100"/>
    <joint_properties damping="0.7"/>
		<origin xyz="0 0 0" rpy="0 0 0"/>
		<parent link="p3at_back_${suffix}_hub"/>
		<child link="p3at_back_${suffix}_wheel"/>
	</joint>
	
  <gazebo reference="p3at_back_${suffix}_wheel">
    <kp>1000000.0</kp> <!-- kp and kd for rubber -->
    <kd>100.0</kd>
    <mu1>10.0</mu1>
    <mu2>10.0</mu2>
    <fdir1>0 1 0</fdir1> <!-- is this correct? -->
    <maxVel>0.7</maxVel>
    <minDepth>0.00</minDepth>
  </gazebo>
  
  <gazebo reference="p3at_front_${suffix}_wheel">
    <kp>1000000.0</kp> <!-- kp and kd for rubber -->
    <kd>100.0</kd>
    <mu1>10.0</mu1>
    <mu2>10.0</mu2>
    <fdir1>0 1 0</fdir1> <!-- is this correct? -->
    <maxVel>0.7</maxVel>
    <minDepth>0.00</minDepth>
  </gazebo>

</xacro:macro>

<xacro:macro name="p3at_gazebo_ext">

  <gazebo>
    <plugin name="skid_steer_drive_controller" filename="libgazebo_ros_skid_steer_drive.so">
      <updateRate>100.0</updateRate>
      <robotNamespace>/</robotNamespace>
      <leftFrontJoint>p3at_front_left_wheel_joint</leftFrontJoint>
      <rightFrontJoint>p3at_front_right_wheel_joint</rightFrontJoint>
      <leftRearJoint>p3at_back_left_wheel_joint</leftRearJoint>
      <rightRearJoint>p3at_back_right_wheel_joint</rightRearJoint>
      <wheelSeparation>0.4</wheelSeparation>
      <wheelDiameter>0.215</wheelDiameter>
      <robotBaseFrame>mobile_link</robotBaseFrame>
      <torque>200</torque>
      <topicName>cmd_vel</topicName>
    </plugin>
  </gazebo>

</xacro:macro>

</robot>
